fill ~-24 ~11 ~20 ~-31 ~17 ~26 minecraft:air
fill ~-32 ~12 ~21 ~-33 ~16 ~25 minecraft:air

fill ~-26 ~12 ~21 ~-26 ~16 ~25 minecraft:oak_planks
fill ~-26 ~13 ~21 ~-26 ~13 ~25 minecraft:stripped_oak_wood
fill ~-26 ~15 ~21 ~-26 ~15 ~25 minecraft:stripped_oak_wood

setblock ~-26 ~12 ~21 minecraft:smooth_stone
setblock ~-26 ~16 ~21 minecraft:smooth_stone
setblock ~-26 ~12 ~25 minecraft:smooth_stone
setblock ~-26 ~16 ~25 minecraft:smooth_stone

setblock ~-25 ~12 ~21 minecraft:stone_button[face=wall,facing=east,powered=false]
setblock ~-25 ~14 ~21 minecraft:stone_button[face=wall,facing=east,powered=false]
setblock ~-25 ~16 ~21 minecraft:stone_button[face=wall,facing=east,powered=false]
setblock ~-25 ~12 ~23 minecraft:stone_button[face=wall,facing=east,powered=false]
setblock ~-25 ~16 ~23 minecraft:stone_button[face=wall,facing=east,powered=false]
setblock ~-25 ~12 ~25 minecraft:stone_button[face=wall,facing=east,powered=false]
setblock ~-25 ~14 ~25 minecraft:stone_button[face=wall,facing=east,powered=false]
setblock ~-25 ~16 ~25 minecraft:stone_button[face=wall,facing=east,powered=false]

setblock ~-25 ~14 ~23 minecraft:light[level=15]
setblock ~-27 ~17 ~23 minecraft:light[level=15]

setblock ~-26 ~11 ~21 minecraft:iron_trapdoor[half=top]
setblock ~-26 ~12 ~20 minecraft:iron_trapdoor[open=true]
setblock ~-26 ~17 ~21 minecraft:iron_trapdoor
setblock ~-26 ~16 ~20 minecraft:iron_trapdoor[open=true]

setblock ~-26 ~11 ~23 minecraft:iron_trapdoor[half=top]
setblock ~-26 ~17 ~23 minecraft:iron_trapdoor

setblock ~-26 ~11 ~25 minecraft:iron_trapdoor[half=top]
setblock ~-26 ~12 ~26 minecraft:iron_trapdoor[open=true,facing=south]
setblock ~-26 ~17 ~25 minecraft:iron_trapdoor
setblock ~-26 ~16 ~26 minecraft:iron_trapdoor[open=true,facing=south]

fill ~-27 ~13 ~21 ~-28 ~15 ~25 minecraft:stone_brick_wall
fill ~-29 ~14 ~22 ~-33 ~14 ~24 minecraft:cobblestone_wall
fill ~-29 ~15 ~23 ~-33 ~15 ~23 minecraft:cobblestone_slab
fill ~-29 ~13 ~23 ~-33 ~13 ~23 minecraft:cobblestone_slab[type=top]

fill ~-27 ~12 ~21 ~-28 ~12 ~25 minecraft:stone_bricks
fill ~-27 ~16 ~21 ~-28 ~16 ~25 minecraft:cracked_stone_bricks
fill ~-28 ~16 ~22 ~-28 ~16 ~24 minecraft:stone_brick_stairs[half=top,facing=east]
fill ~-28 ~12 ~22 ~-28 ~12 ~24 minecraft:stone_brick_stairs[half=bottom,facing=east]

setblock ~-27 ~16 ~21 minecraft:stone_bricks
setblock ~-28 ~16 ~21 minecraft:stone_bricks
setblock ~-27 ~16 ~23 minecraft:stone_bricks